Workbook

Sheet map7
A1: № точки | B1: Адрес | C1: Широта | D1: Долгота | E1: инспектор | F1: Список | G1: Время/дата входа | H1: Время/дата выхода | I1: Время на объекте | J1: Ссылка на чек | K1: Ссылка на яндекс | L1: Предыдущий инспектор | M1: Инспектор | N1: Время открытия рабочего дня | O1: Координаты открытия дня | P1: Время закрытия рабочего дня | Q1: Координаты закрытия дня
M2: Наволокин Андрей Александрович | N2: 45975.37 | O2: 55.891891891891895, 37.497629338494576
M3: Поляков Сергей Алексеевич | N3: 45975.364 | O3: 55.972911479310675, 37.431479050169955
M4: Лашин Александр Николаевич | N4: 45975.37 | O4: 55.7991937, 37.777514
M5: Джинджолия Леван Раульевич | N5: 45975.35 | O5: 55.712123749999996, 37.737975
M6: Гытлан Роман Валентинович | N6: 45975.357 | O6: 55.6724904, 37.7444511
M7: Удалкин Иван Вячеславович | N7: 45975.368 | O7: 55.63512225578537, 37.64980215579271
M8: Осипенко Юрий Владимирович | N8: 45975.365 | O8: 55.3860511, 37.4123357
M9: Данилов Семен Юрьевич | N9: 45975.357 | O9: 55.3084117, 37.3676117
M10: Терехин Александр Андреевич | N10: 45975.374 | O10: 55.5761512, 37.236635
M11: Пулатов Алекс Шухратович | N11: 45975.358 | O11: 55.6803906, 37.3412664
M12: Макаров Илья Алексеевич
M13: Куликов Илья Александрович
M14: Шурпаев Нажмутдин Гаджиатаевич
M15: Старостин Кирилл Владимирович
M16: Дрозд Александр Викторович | N16: 45975.35 | O16: 55.7002553, 37.7818266
M17: Иванов Иван Иванович
A18: 713 | B18: =VLOOKUP($A18,'Реестр объектов'!$A:$I,5,0) -> Веерная улица, земельный участок 28А район Очаково-Матвеевское, ул. Веерная, вл. 28А | C18: =VLOOKUP($A18,'Реестр объектов'!$A:$I,6,0) -> 55.710226 | D18: =VLOOKUP($A18,'Реестр объектов'!$A:$I,7,0) -> 37.480970 | E18: Admin | F18: МФР 26 | J18: =VLOOKUP($A18,'Реестр объектов'!$A:$I,8,0) -> https://docs.google.com/spreadsheets/d/1rbCD10ySi4YZEkJW2_Slmn9z7AI1WEsGsZaIJmnnT18/edit?gid=1754531219#gid=1754531219 | K18: =VLOOKUP($A18,'Реестр объектов'!$A:$I,9,0) -> https://disk.yandex.ru/client/disk/Осмотры%20объектов%20АНО%20СМГ/713.%20Жилой%20дом%20ул.%20Веерная%2028а
A19: 700 | B19: =VLOOKUP($A19,'Реестр объектов'!$A:$I,5,0) -> Жилой дом с подземной автостоянкой, инженерными сетями и благоустройством территории по адресу: район Нагатино-Садовники, Нагатинская ул, вл.1/4 (Нагатинская ул, вл.1) район Нагатино-Садовники, Нагатинская ул, вл.1/4 (Нагатинская ул, вл.1) | C19: =VLOOKUP($A19,'Реестр объектов'!$A:$I,6,0) -> 55.684985 | D19: =VLOOKUP($A19,'Реестр объектов'!$A:$I,7,0) -> 37.624634 | E19: Гытлан Роман Валентинович | F19: МФР 26 | J19: =VLOOKUP($A19,'Реестр объектов'!$A:$I,8,0) -> https://docs.google.com/spreadsheets/d/1rbCD10ySi4YZEkJW2_Slmn9z7AI1WEsGsZaIJmnnT18/edit?gid=732973558#gid=732973558 | K19: =VLOOKUP($A19,'Реестр объектов'!$A:$I,9,0) -> https://disk.yandex.ru/client/disk/Осмотры%20объектов%20АНО%20СМГ/700.%20Нагатинская%20ул.%20вл.%201.%20Жилой%09дом
A20: 738 | B20: =VLOOKUP($A20,'Реестр объектов'!$A:$I,5,0) -> ул. Шепелюгинская, вл. 14 район Лефортово, ул. Шепелюгинская, вл. 14 | C20: =VLOOKUP($A20,'Реестр объектов'!$A:$I,6,0) -> 55.745914 | D20: =VLOOKUP($A20,'Реестр объектов'!$A:$I,7,0) -> 37.702358 | E20: Джинджолия Леван Раульевич | F20: МФР 26 | G20: 45975.502 | J20: =VLOOKUP($A20,'Реестр объектов'!$A:$I,8,0) -> https://docs.google.com/spreadsheets/d/1rbCD10ySi4YZEkJW2_Slmn9z7AI1WEsGsZaIJmnnT18/edit?gid=2128103220#gid=2128103220 | K20: =VLOOKUP($A20,'Реестр объектов'!$A:$I,9,0) -> https://disk.yandex.ru/client/disk/%D0%9E%D1%81%D0%BC%D0%BE%D1%82%D1%80%D1%8B%20%D0%BE%D0%B1%D1%8A%D0%B5%D0%BA%D1%82%D0%BE%D0%B2%20%D0%90%D0%9D%D0%9E%20%D0%A1%D0%9C%D0%93/738.%20%D0%A8%D0%B5%D0%BF%D0%B5%D0%BB%D1%8E%D0%B3%D0%B8%D0%BD%D1%81%D0%BA%D0%B0%D1%8F%20%D0%B2%D0%BB%2014%20
A21: 740 | B21: =VLOOKUP($A21,'Реестр объектов'!$A:$I,5,0) -> Шепелюгинский пер., вл. 7 (Приобретение объектов недвижимости) район Лефортово, Шепелюгинский пер., вл. 7 | C21: =VLOOKUP($A21,'Реестр объектов'!$A:$I,6,0) -> 55.746929 | D21: =VLOOKUP($A21,'Реестр объектов'!$A:$I,7,0) -> 37.701113 | E21: Джинджолия Леван Раульевич | F21: МФР 26 | J21: =VLOOKUP($A21,'Реестр объектов'!$A:$I,8,0) -> https://docs.google.com/spreadsheets/d/1rbCD10ySi4YZEkJW2_Slmn9z7AI1WEsGsZaIJmnnT18/edit?gid=1195206502#gid=1195206502 | K21: =VLOOKUP($A21,'Реестр объектов'!$A:$I,9,0) -> https://disk.yandex.ru/client/disk/Осмотры%20объектов%20АНО%20СМГ/740.%20Шепелюгинский%20пер%20вл%207
A22: 661 | B22: =VLOOKUP($A22,'Реестр объектов'!$A:$I,5,0) -> б-р Яна Райниса, вл.2, к 2,3 район Северное Тушино, мкр. 4, б-р Яна Райниса, вл.2, к 2,3. | C22: =VLOOKUP($A22,'Реестр объектов'!$A:$I,6,0) -> 55.852135 | D22: =VLOOKUP($A22,'Реестр объектов'!$A:$I,7,0) -> 37.431852 | E22: Поляков Сергей Алексеевич | F22: МФР 26 | J22: =VLOOKUP($A22,'Реестр объектов'!$A:$I,8,0) -> https://docs.google.com/spreadsheets/d/1rbCD10ySi4YZEkJW2_Slmn9z7AI1WEsGsZaIJmnnT18/edit?gid=988598667#gid=988598667 | K22: =VLOOKUP($A22,'Реестр объектов'!$A:$I,9,0) -> https://disk.yandex.ru/client/disk/Осмотры%20объектов%20АНО%20СМГ/661.%20Яна%20Райниса%20б-р%2C%20влд.%202%2C%20к.%202%2C%203 | L22: Поляков Сергей Алексеевич
A23: 636 | B23: =VLOOKUP($A23,'Реестр объектов'!$A:$I,5,0) -> улица Смольная,земельный участок 23 внутригородское муниципальное образование Головинское, улица Смольная,земельный участок 23 (ул. Смольная, 23) | C23: =VLOOKUP($A23,'Реестр объектов'!$A:$I,6,0) -> 55.849033 | D23: =VLOOKUP($A23,'Реестр объектов'!$A:$I,7,0) -> 37.494706 | E23: Admin | F23: МФР 26 | J23: =VLOOKUP($A23,'Реестр объектов'!$A:$I,8,0) -> https://docs.google.com/spreadsheets/d/1rbCD10ySi4YZEkJW2_Slmn9z7AI1WEsGsZaIJmnnT18/edit?gid=1665166606#gid=1665166606 | K23: =VLOOKUP($A23,'Реестр объектов'!$A:$I,9,0) -> https://disk.yandex.ru/client/disk/Осмотры%20объектов%20АНО%20СМГ/636.%20Смольная%20зу%2023
A24: 624 | B24: =VLOOKUP($A24,'Реестр объектов'!$A:$I,5,0) -> улица Тайнинская, земельный участок 3 (вл. 3) район Лосиноостровский, Тайнинская ул., вл. 3 | C24: =VLOOKUP($A24,'Реестр объектов'!$A:$I,6,0) -> 55.878112 | D24: =VLOOKUP($A24,'Реестр объектов'!$A:$I,7,0) -> 37.681312 | E24: Admin | F24: МФР 26 | J24: =VLOOKUP($A24,'Реестр объектов'!$A:$I,8,0) -> https://docs.google.com/spreadsheets/d/1rbCD10ySi4YZEkJW2_Slmn9z7AI1WEsGsZaIJmnnT18/edit?gid=1331480544#gid=1331480544 | K24: =VLOOKUP($A24,'Реестр объектов'!$A:$I,9,0) -> https://disk.yandex.ru/client/disk/Осмотры%20объектов%20АНО%20СМГ/624.%20Тайнинская%20ул.%2C%20зу%203
A25: 802 | B25: =VLOOKUP($A25,'Реестр объектов'!$A:$I,5,0) -> Кржижановского ул., вл. 31 район Котловка Кржижановского ул., вл. 31 микрорайонов 67,68, кварталов 103,104,105,106 за границами ППТ | C25: =VLOOKUP($A25,'Реестр объектов'!$A:$I,6,0) -> 55.673297 | D25: =VLOOKUP($A25,'Реестр объектов'!$A:$I,7,0) -> 37.581276 | E25: Удалкин Иван Вячеславович | F25: МФР 26 | G25: 45975.47 | J25: =VLOOKUP($A25,'Реестр объектов'!$A:$I,8,0) -> https://docs.google.com/spreadsheets/d/1rbCD10ySi4YZEkJW2_Slmn9z7AI1WEsGsZaIJmnnT18/edit?gid=79728110#gid=79728110 | K25: =VLOOKUP($A25,'Реестр объектов'!$A:$I,9,0) -> https://disk.yandex.ru/client/disk/Осмотры%20объектов%20АНО%20СМГ/802.%20Котловка%2C%20ул.%20Кржижановского%20вл.%2031
A26: 805 | B26: =VLOOKUP($A26,'Реестр объектов'!$A:$I,5,0) -> Нижегородская ул., з/у 92А (зона №2.4) кв. 80, район Нижегородский (зона № 2.4) (ул. Нижегородская, д. 94, к.2) | C26: =VLOOKUP($A26,'Реестр объектов'!$A:$I,6,0) -> 55.729701 | D26: =VLOOKUP($A26,'Реестр объектов'!$A:$I,7,0) -> 37.721204 | E26: Джинджолия Леван Раульевич | F26: МФР 26 | G26: 45975.465 | H26: 45975.493 | I26: 40 мин | J26: =VLOOKUP($A26,'Реестр объектов'!$A:$I,8,0) -> https://docs.google.com/spreadsheets/d/1rbCD10ySi4YZEkJW2_Slmn9z7AI1WEsGsZaIJmnnT18/edit?gid=1527817991#gid=1527817991 | K26: =VLOOKUP($A26,'Реестр объектов'!$A:$I,9,0) -> https://disk.yandex.ru/client/disk/Осмотры%20объектов%20АНО%20СМГ/805.%20Нижегородская%20ул.%2C%20з-у%2092А%2C%20зона%202.4
A27: 609 | B27: =VLOOKUP($A27,'Реестр объектов'!$A:$I,5,0) -> ул. Лобачевского, влд. 62 район Проспект Вернадского, Лобачевского ул., вл. 62 | C27: =VLOOKUP($A27,'Реестр объектов'!$A:$I,6,0) -> 55.675595 | D27: =VLOOKUP($A27,'Реестр объектов'!$A:$I,7,0) -> 37.492644 | E27: Admin | F27: МФР 26 | J27: =VLOOKUP($A27,'Реестр объектов'!$A:$I,8,0) -> https://docs.google.com/spreadsheets/d/1rbCD10ySi4YZEkJW2_Slmn9z7AI1WEsGsZaIJmnnT18/edit?gid=387655725#gid=387655725 | K27: =VLOOKUP($A27,'Реестр объектов'!$A:$I,9,0) -> https://disk.yandex.ru/client/disk/Осмотры%20объектов%20АНО%20СМГ/609.%20ЗАО%20проспект%20Вернадского%2C%20Лобачевского%20улица.%2C%20вл.62
A28: 644 | B28: =VLOOKUP($A28,'Реестр объектов'!$A:$I,5,0) -> 9 Мая ул., вл. 24 район Восточный, 9 Мая ул., вл. 24 | C28: =VLOOKUP($A28,'Реестр объектов'!$A:$I,6,0) -> 55.818169 | D28: =VLOOKUP($A28,'Реестр объектов'!$A:$I,7,0) -> 37.872541 | E28: Лашин Александр Николаевич | F28: МФР 26 | J28: =VLOOKUP($A28,'Реестр объектов'!$A:$I,8,0) -> https://docs.google.com/spreadsheets/d/1rbCD10ySi4YZEkJW2_Slmn9z7AI1WEsGsZaIJmnnT18/edit?gid=692135392#gid=692135392 | K28: =VLOOKUP($A28,'Реестр объектов'!$A:$I,9,0) -> https://disk.yandex.ru/client/disk/%D0%9E%D1%81%D0%BC%D0%BE%D1%82%D1%80%D1%8B%20%D0%BE%D0%B1%D1%8A%D0%B5%D0%BA%D1%82%D0%BE%D0%B2%20%D0%90%D0%9D%D0%9E%20%D0%A1%D0%9C%D0%93/644%20%D0%A3%D0%BB.%209%20%D0%9C%D0%B0%D1%8F%20%D0%B2%D0%BB%2024%20%D1%80-%D0%BD%20%D0%92%D0%BE%D1%81%D1%82%D0%BE%D1%87%D0%BD%D1%8B%D0%B9%2C%20%D1%81%D0%BE%20%D1%81%D0%BD%D0%BE%D1%81%D0%BE%D0%BC%20%D0%96.%D0%A1.%20%20
A29: 605 | B29: =VLOOKUP($A29,'Реестр объектов'!$A:$I,5,0) -> 1-й Саратовский пр-д, з/у 5 (1-й Саратовский пр-д, вл.5) район Текстильщики, 1-й Саратовский пр-д, вл.5 | C29: =VLOOKUP($A29,'Реестр объектов'!$A:$I,6,0) -> 55.711841 | D29: =VLOOKUP($A29,'Реестр объектов'!$A:$I,7,0) -> 37.737222 | E29: Джинджолия Леван Раульевич | F29: МФР 26 | G29: 45975.354 | H29: 45975.381 | I29: 39 мин | J29: =VLOOKUP($A29,'Реестр объектов'!$A:$I,8,0) -> https://docs.google.com/spreadsheets/d/1rbCD10ySi4YZEkJW2_Slmn9z7AI1WEsGsZaIJmnnT18/edit?gid=847490134#gid=847490134 | K29: =VLOOKUP($A29,'Реестр объектов'!$A:$I,9,0) -> https://disk.yandex.ru/client/disk/Осмотры%20объектов%20АНО%20СМГ/605.%201-й%20Саратовский%20проезд%2C%205%20Реновация
A30: 728 | B30: =VLOOKUP($A30,'Реестр объектов'!$A:$I,5,0) -> ул. 2-я Синичкина, з/у 9 (ул. 2-я Синичкина, вл. 9) район Лефортово, улица 2-я Синичкина, земельный участок 9 (ул. 2-я Синичкина, вл. 9) | C30: =VLOOKUP($A30,'Реестр объектов'!$A:$I,6,0) -> 55.763275 | D30: =VLOOKUP($A30,'Реестр объектов'!$A:$I,7,0) -> 37.712926 | E30: Admin | F30: МФР 26 | J30: =VLOOKUP($A30,'Реестр объектов'!$A:$I,8,0) -> https://docs.google.com/spreadsheets/d/1rbCD10ySi4YZEkJW2_Slmn9z7AI1WEsGsZaIJmnnT18/edit?gid=943458292#gid=943458292 | K30: =VLOOKUP($A30,'Реестр объектов'!$A:$I,9,0) -> https://disk.yandex.ru/client/disk/%D0%9E%D1%81%D0%BC%D0%BE%D1%82%D1%80%D1%8B%20%D0%BE%D0%B1%D1%8A%D0%B5%D0%BA%D1%82%D0%BE%D0%B2%20%D0%90%D0%9D%D0%9E%20%D0%A1%D0%9C%D0%93/728.%20%D1%80%D0%B0%D0%B9%D0%BE%D0%BD%20%D0%9B%D0%B5%D1%84%D0%BE%D1%80%D1%82%D0%BE%D0%B2%D0%BE%2C%202-%D1%8F%20%D0%A1%D0%B8%D0%BD%D0%B8%D1%87%D0%BA%D0%B8%D0%BD%D0%B0%2C%20%D0%B7.%D1%83%209%20(%D1%81%D0%BE%20%D1%81%D0%BD%D0%BE%D1%81%D0%BE%D0%BC%20%D0%B6%D0%B8%D0%BB%D0%BE%D0%B3%D0%BE%20%D0%B4%D0%BE%D0%BC%D0%B0%20%D0%BF%D0%BE%20%D0%B0%D0%B4%D1%80%D0%B5%D1%81%D1%83%3A%202-%D1%8F%20%D1%83%D0%BB%D0%B8%D1%86%D0%B0%20%D0%A1%D0%B8%D0%BD%D0%B8%D1%87%D0%BA%D0%B8%D0%BD%D0%B0%2C%20%D0%B4%D0%BE%D0%BC%209)
A31: 645 | B31: =VLOOKUP($A31,'Реестр объектов'!$A:$I,5,0) -> Щербаковская ул., влд. 5А район Соколиная гора, Щербаковская улица, влд. 5А | C31: =VLOOKUP($A31,'Реестр объектов'!$A:$I,6,0) -> 55.783473 | D31: =VLOOKUP($A31,'Реестр объектов'!$A:$I,7,0) -> 37.725236 | E31: Admin | F31: МФР 26 | J31: =VLOOKUP($A31,'Реестр объектов'!$A:$I,8,0) -> https://docs.google.com/spreadsheets/d/1rbCD10ySi4YZEkJW2_Slmn9z7AI1WEsGsZaIJmnnT18/edit?gid=1166394533#gid=1166394533 | K31: =VLOOKUP($A31,'Реестр объектов'!$A:$I,9,0) -> https://disk.yandex.ru/client/disk/%D0%9E%D1%81%D0%BC%D0%BE%D1%82%D1%80%D1%8B%20%D0%BE%D0%B1%D1%8A%D0%B5%D0%BA%D1%82%D0%BE%D0%B2%20%D0%90%D0%9D%D0%9E%20%D0%A1%D0%9C%D0%93/645.%20%D0%A9%D0%B5%D1%80%D0%B1%D0%B0%D0%BA%D0%BE%D0%B2%D1%81%D0%BA%D0%B0%D1%8F%20%D0%B7%D1%83%205%D0%90%20
A32: 550 | B32: =VLOOKUP($A32,'Реестр объектов'!$A:$I,5,0) -> гор.Щербинка, 40 лет Октября ул., з/у 12 ТиНАО, г.о. Щербинка, ул. 40 лет Октября, з/у 12 (Симферопольская ул., д. 2, ул. 40 лет Октября, д. 12, д. 16/1) | C32: =VLOOKUP($A32,'Реестр объектов'!$A:$I,6,0) -> 55.510648 | D32: =VLOOKUP($A32,'Реестр объектов'!$A:$I,7,0) -> 37.572771 | E32: Admin | F32: МФР 26 | J32: =VLOOKUP($A32,'Реестр объектов'!$A:$I,8,0) -> https://docs.google.com/spreadsheets/d/1rbCD10ySi4YZEkJW2_Slmn9z7AI1WEsGsZaIJmnnT18/edit?gid=811633138#gid=811633138 | K32: =VLOOKUP($A32,'Реестр объектов'!$A:$I,9,0) -> https://disk.yandex.ru/client/disk/Осмотры%20объектов%20АНО%20СМГ/550.%20г.о.%20Щербинка%2C%20ул.%2040%20лет%20Октября%2C%20з.у%2012%20Симферопольская%20ул.%2C%20д.%202%2C%20ул.%2040%20лет%20Октября%2C%20д.%2012%2C%20д.%2016.1)
A33: 655 | B33: =VLOOKUP($A33,'Реестр объектов'!$A:$I,5,0) -> ул. Корнейчука, вл.47А СВАО, район Бибирево, ул. Корнейчука, вл. 47А (со сносом здания по адресу: ул. Корнейчука, д. 47А) | C33: =VLOOKUP($A33,'Реестр объектов'!$A:$I,6,0) -> 55.893110 | D33: =VLOOKUP($A33,'Реестр объектов'!$A:$I,7,0) -> 37.630685 | E33: Admin | F33: МФР 26 | J33: =VLOOKUP($A33,'Реестр объектов'!$A:$I,8,0) -> https://docs.google.com/spreadsheets/d/1rbCD10ySi4YZEkJW2_Slmn9z7AI1WEsGsZaIJmnnT18/edit?gid=1300345470#gid=1300345470 | K33: =VLOOKUP($A33,'Реестр объектов'!$A:$I,9,0) -> https://disk.yandex.ru/client/disk/Осмотры%20объектов%20АНО%20СМГ/655.%20ул.%20Корнейчука%2C%20вл.%2047%20А
A34: 712 | B34: =VLOOKUP($A34,'Реестр объектов'!$A:$I,5,0) -> ул. Большая Очаковская, з/у 45А (Большая Очаковская ул., вл.45А) ЗАО, район Очаково - Матвеевское, Большая Очаковская, влд. 45А, квартал 2,4 зона 15.1 (со сносом жилых зданий по адресу: ул. Большая Очаковская, 45 к.1, ул. Проектируемый проезд №1980, д.3) | C34: =VLOOKUP($A34,'Реестр объектов'!$A:$I,6,0) -> 55.674464 | D34: =VLOOKUP($A34,'Реестр объектов'!$A:$I,7,0) -> 37.446148 | E34: Admin | F34: МФР 26 | J34: =VLOOKUP($A34,'Реестр объектов'!$A:$I,8,0) -> https://docs.google.com/spreadsheets/d/1rbCD10ySi4YZEkJW2_Slmn9z7AI1WEsGsZaIJmnnT18/edit?gid=1525507838#gid=1525507838 | K34: =VLOOKUP($A34,'Реестр объектов'!$A:$I,9,0) -> https://disk.yandex.ru/client/disk/Осмотры%20объектов%20АНО%20СМГ/712.%20Большая%20Очаковская%2C%20влд.%2045А%2C%20квартал%202%2C4%20зона%2015.1
A35: 698 | B35: =VLOOKUP($A35,'Реестр объектов'!$A:$I,5,0) -> Шишкин Лес, зона 6.2 ТАО, пос. Михайлово-Ярцевское, п. Шишкин Лес, з/у 5 зона № 6.2 | C35: =VLOOKUP($A35,'Реестр объектов'!$A:$I,6,0) -> 55.413660 | D35: =VLOOKUP($A35,'Реестр объектов'!$A:$I,7,0) -> 37.192563 | E35: Осипенко Юрий Владимирович | F35: МФР 26 | J35: =VLOOKUP($A35,'Реестр объектов'!$A:$I,8,0) -> https://docs.google.com/spreadsheets/d/1rbCD10ySi4YZEkJW2_Slmn9z7AI1WEsGsZaIJmnnT18/edit?gid=1721879742#gid=1721879742 | K35: =VLOOKUP($A35,'Реестр объектов'!$A:$I,9,0) -> https://disk.yandex.ru/client/disk/Осмотры%20объектов%20АНО%20СМГ/698.%20пос.%20Михайлово-Ярцевское%2C%20п.%20Шишкин%20Лес%2C%20зу%205%20зона%20№%206.2
A36: 653 | B36: =VLOOKUP($A36,'Реестр объектов'!$A:$I,5,0) -> ул. Госпитальный Вал, вл.5, корп.10 , ул. Госпитальный Вал, д.5, стр.20; ул. Госпитальный Вал, д.5, к.10) ЦАО, район Басманный, ул. Госпитальный Вал, вл.5, корп.20 (со сносом нежилого здания ГБОУ школа на Яузе Дошкольное отделение корпус № 7 по адресу: ул. Госпитальный Вал, д.5, стр.20 и жилого дома по адресу: ул. Госпитальный Вал, д.5, к.10) | C36: =VLOOKUP($A36,'Реестр объектов'!$A:$I,6,0) -> 55.772856 | D36: =VLOOKUP($A36,'Реестр объектов'!$A:$I,7,0) -> 37.708026 | E36: Admin | F36: МФР 26 | J36: =VLOOKUP($A36,'Реестр объектов'!$A:$I,8,0) -> https://docs.google.com/spreadsheets/d/1rbCD10ySi4YZEkJW2_Slmn9z7AI1WEsGsZaIJmnnT18/edit?gid=1637195585#gid=1637195585 | K36: =VLOOKUP($A36,'Реестр объектов'!$A:$I,9,0) -> https://disk.yandex.ru/client/disk/Осмотры%20объектов%20АНО%20СМГ/653.%20Госпитальный%20Вал%20ул.%2C%20вл.%205%2C%20Корп.20
A37: 694 | B37: =VLOOKUP($A37,'Реестр объектов'!$A:$I,5,0) -> ул. Госпитальный Вал, вл.3 ЦАО, район Басманный, ул. Госпитальный Вал, вл.3 (со сносом жилых домов по адресам: ул. Госпитальный Вал, д.3 и д.3, корп.1) | C37: =VLOOKUP($A37,'Реестр объектов'!$A:$I,6,0) -> 55.772318 | D37: =VLOOKUP($A37,'Реестр объектов'!$A:$I,7,0) -> 37.706787 | E37: Admin | F37: МФР 26 | J37: =VLOOKUP($A37,'Реестр объектов'!$A:$I,8,0) -> https://docs.google.com/spreadsheets/d/1rbCD10ySi4YZEkJW2_Slmn9z7AI1WEsGsZaIJmnnT18/edit?gid=1429286292#gid=1429286292 | K37: =VLOOKUP($A37,'Реестр объектов'!$A:$I,9,0) -> https://disk.yandex.ru/client/disk/Осмотры%20объектов%20АНО%20СМГ/694.%20Госпитальный%20Вал%20ул.%2C%20вл.%203
A38: 666 | B38: =VLOOKUP($A38,'Реестр объектов'!$A:$I,5,0) -> ул. Константинова, з/у 2 (ул. Константинова, вл. 2) СВАО, район Алексеевский, ул. Константинова, влд. 2 | C38: =VLOOKUP($A38,'Реестр объектов'!$A:$I,6,0) -> 55.813415 | D38: =VLOOKUP($A38,'Реестр объектов'!$A:$I,7,0) -> 37.652562 | E38: Admin | F38: МФР 26 | J38: =VLOOKUP($A38,'Реестр объектов'!$A:$I,8,0) -> https://docs.google.com/spreadsheets/d/1rbCD10ySi4YZEkJW2_Slmn9z7AI1WEsGsZaIJmnnT18/edit?gid=989644917#gid=989644917 | K38: =VLOOKUP($A38,'Реестр объектов'!$A:$I,9,0) -> https://disk.yandex.ru/client/disk/Осмотры%20объектов%20АНО%20СМГ/666.%20Константинова%20ул.%2C%20вл.%202
A39: 961 | B39: =VLOOKUP($A39,'Реестр объектов'!$A:$I,5,0) -> пр-д Береговой, з/у 9/1 (Береговой пр-д, вл.9, корп.1) район Филевский парк, Береговой пр-д, вл. 9, корп. 1 | C39: =VLOOKUP($A39,'Реестр объектов'!$A:$I,6,0) -> 55.754325 | D39: =VLOOKUP($A39,'Реестр объектов'!$A:$I,7,0) -> 37.504466 | E39: Admin | F39: МФР 26 | J39: =VLOOKUP($A39,'Реестр объектов'!$A:$I,8,0) -> https://docs.google.com/spreadsheets/d/1rbCD10ySi4YZEkJW2_Slmn9z7AI1WEsGsZaIJmnnT18/edit?gid=3034090#gid=3034090 | K39: =VLOOKUP($A39,'Реестр объектов'!$A:$I,9,0) -> https://disk.yandex.ru/client/disk/Осмотры%20объектов%20АНО%20СМГ/961.%20Жилой%20дом%20Береговой%20проезд%209к1
A40: 673 | B40: =VLOOKUP($A40,'Реестр объектов'!$A:$I,5,0) -> Велозаводская ул., з/у 2 ЮАО, район Даниловский, Велозаводская ул., вл.2 | C40: =VLOOKUP($A40,'Реестр объектов'!$A:$I,6,0) -> 55.715704 | D40: =VLOOKUP($A40,'Реестр объектов'!$A:$I,7,0) -> 37.663933 | E40: Гытлан Роман Валентинович | F40: МФР 26 | J40: =VLOOKUP($A40,'Реестр объектов'!$A:$I,8,0) -> https://docs.google.com/spreadsheets/d/1rbCD10ySi4YZEkJW2_Slmn9z7AI1WEsGsZaIJmnnT18/edit?gid=1509964288#gid=1509964288 | K40: =VLOOKUP($A40,'Реестр объектов'!$A:$I,9,0) -> https://disk.yandex.ru/client/disk/Осмотры%20объектов%20АНО%20СМГ/673.%20Велозаводская%20ул.%2C%20з.у%202
...

Sheet map7 (копия)
A1: № точки | B1: Адрес | C1: Широта | D1: Долгота | E1: инспектор | F1: Список | G1: Время/дата входа | H1: Время/дата выхода | I1: Время на объекте | J1: Ссылка на чек | K1: Ссылка на яндекс | L1: Предыдущий инспектор | M1: Инспектор | N1: Время открытия рабочего дня | O1: Координаты открытия дня | P1: Время закрытия рабочего дня | Q1: Координаты закрытия дня
M2: Наволокин Андрей Александрович | N2: 45974.369 | O2: 55.891891891891895, 37.497629338494576 | P2: 45974.753 | Q2: 55.891891891891895, 37.56189262784932
M3: Поляков Сергей Алексеевич | N3: 45974.369 | O3: 55.8582975715919, 37.56338548850041 | P3: 45974.754 | Q3: 55.97331960752988, 37.43128846985928
M4: Лашин Александр Николаевич | N4: 45974.374 | O4: 55.8065928, 37.7505764 | P4: 45974.753 | Q4: 55.8762665, 37.6928165
M5: Джинджолия Леван Раульевич | N5: 45974.364 | O5: 55.729640671929225, 37.859889534424795 | P5: 45974.752 | Q5: 55.75591697791024, 37.81832386127772
M6: Гытлан Роман Валентинович | N6: 45974.359 | O6: 55.6343384, 37.6832811 | P6: 45974.743 | Q6: 55.6758392, 37.7484568
M7: Удалкин Иван Вячеславович | N7: 45974.369 | O7: 55.7088312, 37.7532142 | P7: 45974.752 | Q7: 55.61714181018449, 37.66326114535332
M8: Осипенко Юрий Владимирович | N8: 45974.37 | O8: 55.6627117, 37.5984287 | P8: 45974.752 | Q8: 55.680911033036686, 37.58400882928834
M9: Данилов Семен Юрьевич | N9: 45974.38 | O9: 55.6564175, 37.5908138 | P9: 45974.749 | Q9: 55.6481499, 37.5780129
M10: Терехин Александр Андреевич | N10: 45974.38 | O10: 55.6294717, 37.336493 | P10: 45974.764 | Q10: 55.6740797, 37.4610087
M11: Пулатов Алекс Шухратович | N11: 45974.403 | O11: 55.7907901, 37.5476043 | P11: 45974.758 | Q11: 55.6359029, 37.3045624
M12: Макаров Илья Алексеевич
M13: Куликов Илья Александрович
M14: Шурпаев Нажмутдин Гаджиатаевич | N14: 45973.372 | O14: 55.7004796, 37.8739557 | P14: 45973.751 | Q14: 55.7095883, 37.8667496
M15: Старостин Кирилл Владимирович
M16: Дрозд Александр Викторович | N16: 45974.36 | O16: 55.7206082, 37.7823076 | P16: 45974.75 | Q16: 55.699569, 37.7860144
M17: Иванов Иван Иванович
A18: 1178 | B18: Общеобразовательная школа №1 на 850 мест Волоколамское шоссе уч. 71/14 (город Москва, вн. тер.г. муниципальный округ Покровское-Стрешнево, улица Николая Озерова, земельный участок 8) | C18: 55.81402855891889 | D18: 37.428749835997806 | E18: Поляков Сергей Алексеевич | F18: МЭР | G18: 45974.427 | H18: 45974.494 | I18: 97 мин | J18: https://docs.google.com/spreadsheets/d/1EI7qusa674eJhuaw-nWWtWMEHVSYMQv7HLsInEZTWpE/edit?gid=623093467#gid=623093467 | K18: https://disk.yandex.ru/client/disk/Осмотры%20объектов%20АНО%20СМГ/1178%20Волоколамское%20шоссе%2C%20вл.%2071%2014%20Школа%20на%20850%20мест | L18: Куликов Илья Александрович
A19: 1338 | B19: Осмотр итогов строительства средней общеобразовательной школы на 1000 мест, корп. 8 ЗАО, ул. Озерная, вл. 42-44 | C19: 55.669999907394924 | D19: 37.43651406872443 | E19: Терехин Александр Андреевич | F19: МЭР | G19: 45973.385 | H19: 45973.472 | I19: 126 мин | J19: https://docs.google.com/spreadsheets/d/1EI7qusa674eJhuaw-nWWtWMEHVSYMQv7HLsInEZTWpE/edit?gid=1412429298#gid=1412429298 | K19: https://disk.yandex.ru/d/q3xDbj1lGRqG7w
A20: 542 | B20: 11-я Парковая улица, земельный участок 55/1 (вл. 55) (зона 72.2 (к. 38)) район Северное Измайлово, 11-я Парковая ул., земельный участок 55/1 (11-я Парковая ул., вл. 55) (зона 72.2 (к.38)) | C20: 55.808673 | D20: 37.802970 | E20: Лашин Александр Николаевич | F20: ОВА26 | G20: 45973.381 | H20: 45973.433 | I20: 75 мин | J20: https://docs.google.com/spreadsheets/d/1H1MjbG2y0oC0hhID4do1G0_gfyI1jag72lQd7nL3WDQ/edit?gid=1320846516#gid=1320846516 | K20: https://disk.yandex.ru/client/disk/Осмотры%20объектов%20АНО%20СМГ/542.%20Северное%20Измайлово%2C%2011-я%20Парковая%20ул.%2055 | L20: Лашин Александр Николаевич
A21: 603 | B21: Жилой дом с подземной автостоянкой, инженерными сетями и благоустройством территории (со сносом жилых зданий по адресам: ул. Бутлерова, д. 34, корп.1; ул. Бутлерова, д. 34, корп.2; ул. Бутлерова, д. 36, корп.1; ул. Бутлерова, д. 36, корп.2), район Коньково, микрорайон 6 района Коньково, зона № 1.2 район Коньково, микрорайон 6 района Коньково, зона № 1.2 (4 корпуса) | C21: 55.643709 | D21: 37.545808 | E21: Терехин Александр Андреевич | F21: ОВА26 | G21: 45973.582 | H21: 45973.657 | I21: 107 мин | J21: https://docs.google.com/spreadsheets/d/1H1MjbG2y0oC0hhID4do1G0_gfyI1jag72lQd7nL3WDQ/edit?gid=1000032786#gid=1000032786 | K21: https://disk.yandex.ru/client/disk/Осмотры%20объектов%20АНО%20СМГ/603.%20район%20Коньково%2C%20ул.%20Бутлерово%20зу%2034_2%20мкр.%206%20зона%201.2 | L21: Удалкин Иван Вячеславович
A22: 631 | B22: Ярославская ул., з/у 2/1 район Алексеевский, Ярославская ул., з/у 2/1 | C22: 55.813806 | D22: 37.647062 | E22: Поляков Сергей Алексеевич | F22: ОВА26 | G22: 45973.427 | H22: 45973.493 | I22: 95 мин | J22: https://docs.google.com/spreadsheets/d/1H1MjbG2y0oC0hhID4do1G0_gfyI1jag72lQd7nL3WDQ/edit?gid=1988948543#gid=1988948543 | K22: https://disk.yandex.ru/client/disk/Осмотры%20объектов%20АНО%20СМГ/631.%20Ярославская%20ул.%2C%20зу%202-1
A23: 650 | B23: Большая Черёмушкинская, з/у 26 ЮЗАО, район Академический, Большая Черемушкинская улица, земельный участок 26 (рефинансирование) | C23: 55.680673 | D23: 37.584110 | E23: Осипенко Юрий Владимирович | F23: ОВА26 | G23: 45974.492 | H23: 45974.751 | I23: 373 мин | J23: https://docs.google.com/spreadsheets/d/1rbCD10ySi4YZEkJW2_Slmn9z7AI1WEsGsZaIJmnnT18/edit?gid=1401788865#gid=1401788865 | K23: https://disk.yandex.ru/client/disk/%D0%9E%D1%81%D0%BC%D0%BE%D1%82%D1%80%D1%8B%20%D0%BE%D0%B1%D1%8A%D0%B5%D0%BA%D1%82%D0%BE%D0%B2%20%D0%90%D0%9D%D0%9E%20%D0%A1%D0%9C%D0%93/650.%20%D0%91%D0%BE%D0%BB%D1%8C%D1%88%D0%B0%D1%8F%20%D0%A7%D0%B5%D1%80%D1%91%D0%BC%D1%83%D1%88%D0%BA%D0%B8%D0%BD%D1%81%D0%BA%D0%B0%D1%8F%20%D0%B7!%D1%83%2026%20(%D1%80%D0%B5%D1%84%D0%B8%D0%BD%D0%B0%D0%BD%D1%81%D0%B8%D1%80%D0%BE%D0%B2%D0%B0%D0%BD%D0%B8%D0%B5) | L23: Дрозд Александр Викторович
A24: 962 | B24: ул. Годовикова, з/у 7 (Годовикова ул., вл.7) район Останкинский, Годовикова ул., вл. 7 | C24: 55.805922 | D24: 37.630109 | E24: Поляков Сергей Алексеевич | F24: ОВА26 | G24: 45973.373 | H24: 45973.42 | I24: 68 мин | J24: https://docs.google.com/spreadsheets/d/1rbCD10ySi4YZEkJW2_Slmn9z7AI1WEsGsZaIJmnnT18/edit?gid=1538306210#gid=1538306210 | K24: https://disk.yandex.ru/client/disk/Осмотры%20объектов%20АНО%20СМГ/962.%20ул.%20Годовикова%2C%20з.у.%207
A25: 1065 | B25: Технологическая часть ТПУ на станции метро "Рассказовка" ("Новопеределкино"). Этап 2.1 Станция метро "Рассказовка" | C25: 55.6329806404929 | D25: 37.3362958431244 | E25: Терехин Александр Андреевич | F25: ТПУ | G25: 45974.387 | H25: 45974.499 | I25: 161 мин | L25: Пулатов Алекс Шухратович
A26: 1134 | B26: Технологическая часть ТПУ на станции метро "Нижегородская". Этап 2 г. Москва , м . "Нижегородская" | C26: 55.73157328033123 | D26: 37.7306499021285 | E26: Шурпаев Нажмутдин Гаджиатаевич | F26: ТПУ | G26: 45973.474 | H26: 45973.515 | I26: 58 мин | L26: Гытлан Роман Валентинович
A27: 1121 | B27: Технологическая часть ТПУ на станции метро "Лианозово". Этап 1 "Устройство УДС улицы Псковская, Дубнинская и Лианозовского проезда, ОРП для электробусов на Дмитровском шоссе. Уширение плоскостной перехватывающей парковки." г. Москва, м. "Лианозово" | C27: 55.896590400864746 | D27: 37.5536087103118 | E27: Наволокин Андрей Александрович | F27: ТПУ | G27: 45973.546 | H27: 45973.638 | I27: 132 мин
A28: 1130 | B28: Технологическая часть ТПУ на станции метро "Лефортово". Этапы 1 г.Москва, м. "Лефортово" | C28: 55.76508268252738 | D28: 37.706975584338856 | E28: Шурпаев Нажмутдин Гаджиатаевич | F28: ТПУ | G28: 45973.587 | H28: 45973.643 | I28: 81 мин | L28: Лашин Александр Николаевич
A29: 1328 | B29: Технологическая часть ТПУ на станции метро "Ховрино" ("ул. Дыбенко"). Этап 4.1 "Технологическая часть транспортно-пересадочноо узла на станции метро "Ховрино" ("Улица Дыбенко"). Развитие транспортной и пешеходной инфраструктуры. Благоустройство Станция метро "Ховрино" | C29: 55.87969632155726 | D29: 37.48327681880147 | E29: Наволокин Андрей Александрович | F29: ТПУ | G29: 45973.367 | H29: 45973.436 | I29: 100 мин
A30: 1020 | B30: Теплоснабжение жилого комплекса с подземной автостоянкой, ул. 4-я Парковая, влд. 16 ВАО г. Москвы, район Измайлово, 4-я Парковая ул.,вл.16 | C30: 55.7948 | D30: 37.7882 | E30: Джинджолия Леван Раульевич | F30: ГС | G30: 45973.548 | H30: 45973.55 | I30: 3 мин | J30: https://docs.google.com/spreadsheets/d/19THEBTE9q0fhN2eApZr6BgenIvLGh0AckaYxHQfHk5w/edit?gid=901281284#gid=901281284 | K30: https://disk.yandex.ru/client/disk/%D0%9E%D1%81%D0%BC%D0%BE%D1%82%D1%80%D1%8B%20%D0%BE%D0%B1%D1%8A%D0%B5%D0%BA%D1%82%D0%BE%D0%B2%20%D0%90%D0%9D%D0%9E%20%D0%A1%D0%9C%D0%93/1020.%20%D1%83%D0%BB.%204-%D1%8F%20%D0%9F%D0%B0%D1%80%D0%BA%D0%BE%D0%B2%D0%B0%D1%8F%2C%20%D0%B2%D0%BB%D0%B4.%2016%20(%D0%A2%D0%B5%D0%BF%D0%BB%D0%BE%D1%81%D0%BD%D0%B0%D0%B1%D0%B6%D0%B5%D0%BD%D0%B8%D0%B5%20%D0%B6%D0%B8%D0%BB%D0%BE%D0%B3%D0%BE%20%D0%BA%D0%BE%D0%BC%D0%BF%D0%BB%D0%B5%D0%BA%D1%81%D0%B0%20%D1%81%20%D0%BF%D0%BE%D0%B4%D0%B7%D0%B5%D0%BC%D0%BD%D0%BE%D0%B9%20%D0%B0%D0%B2%D1%82%D0%BE%D1%81%D1%82%D0%BE%D1%8F%D0%BD%D0%BA%D0%BE%D0%B9) | L30: Лашин Александр Николаевич
A31: 115 | B31: Жилой комплекс «Академ Палас», проспект Вернадского, вл. 78 район Тропарево-Никулино, проспект Вернадского, вл. 78 | C31: 55.667261 | D31: 37.482381 | E31: Терехин Александр Андреевич | F31: ГС | G31: 45973.501 | H31: 45973.549 | I31: 69 мин | J31: https://docs.google.com/spreadsheets/d/19THEBTE9q0fhN2eApZr6BgenIvLGh0AckaYxHQfHk5w/edit?gid=809581458#gid=809581458 | K31: https://disk.yandex.ru/client/disk/Осмотры%20объектов%20АНО%20СМГ/115.%20Жилой%20комплекс%20«Академ%20Палас»%20проспект%20Вернадского%2C%20вл.78
A32: 188 | B32: Жилой дом с подземной автостоянкой(проектно-изыскательские и строительно-монтажные работы по сносу и строительству) район Бутырский, ул. Милашенкова, вл.6 | C32: 55.82384253354808 | D32: 37.58752899867056 | E32: Поляков Сергей Алексеевич | F32: ГС | G32: 45973.515 | H32: 45973.582 | I32: 97 мин | J32: https://docs.google.com/spreadsheets/d/19THEBTE9q0fhN2eApZr6BgenIvLGh0AckaYxHQfHk5w/edit?gid=1559792467#gid=1559792467 | K32: https://disk.yandex.ru/client/disk/Осмотры%20объектов%20АНО%20СМГ/188.%20СВАО%2C%20район%2C%20Бутырский%2C%20ул.%20Милашенкова%2C%20влд.6%09 | L32: Поляков Сергей Алексеевич
A33: 555 | B33: =VLOOKUP($A33,'Реестр объектов'!$A:$I,5,0) -> Севастопольский просп., з/у 46/7 (Севастопольский просп., вблизи д. 46, корп. 7) район Черемушки, Севастопольский пр-кт, вблизи д. 46, к. 7, квартал 32, 33-34, зона № 8.2 | C33: =VLOOKUP($A33,'Реестр объектов'!$A:$I,6,0) -> 55.656958 | D33: =VLOOKUP($A33,'Реестр объектов'!$A:$I,7,0) -> 37.565047 | E33: Осипенко Юрий Владимирович | F33: МФР ШТАБ | G33: 45973.548 | H33: 45973.625 | I33: 111 мин | J33: =VLOOKUP($A33,'Реестр объектов'!$A:$I,8,0) -> https://docs.google.com/spreadsheets/d/1H1MjbG2y0oC0hhID4do1G0_gfyI1jag72lQd7nL3WDQ/edit?gid=1298340576#gid=1298340576 | K33: =VLOOKUP($A33,'Реестр объектов'!$A:$I,9,0) -> https://disk.yandex.ru/client/disk/Осмотры%20объектов%20АНО%20СМГ/555.%20Район%20Черемушки%2C%20Севастопольский%20вблизи%20д46%20к7%2C%20кв%2032%2C33%20зона%208.2
A34: 710 | B34: =VLOOKUP($A34,'Реестр объектов'!$A:$I,5,0) -> Сиреневый бульвар, з/у 4/9, зона 6,1 Сиреневый бульвар, з/у 4/9, зона 6,1 | C34: =VLOOKUP($A34,'Реестр объектов'!$A:$I,6,0) -> 55.796229 | D34: =VLOOKUP($A34,'Реестр объектов'!$A:$I,7,0) -> 37.759937 | E34: Дрозд Александр Викторович | F34: МФР ШТАБ | G34: 45973.706 | H34: 45973.751 | I34: 65 мин | J34: =VLOOKUP($A34,'Реестр объектов'!$A:$I,8,0) -> https://docs.google.com/spreadsheets/d/1H1MjbG2y0oC0hhID4do1G0_gfyI1jag72lQd7nL3WDQ/edit?gid=84528393#gid=84528393 | K34: =VLOOKUP($A34,'Реестр объектов'!$A:$I,9,0) -> https://disk.yandex.ru/client/disk/Осмотры%20объектов%20АНО%20СМГ/710%20Сиреневый%20бульвар%2C%20зу%204%209%2C%20зона%206.1
A35: 532 | B35: =VLOOKUP($A35,'Реестр объектов'!$A:$I,5,0) -> Михайлова ул., з/у 15 (Михайлова ул., вл. 15, корп. 1 и 2) Михайлова ул., з/у 15 (Михайлова ул., вл. 15, корп. 1 и 2) | C35: =VLOOKUP($A35,'Реестр объектов'!$A:$I,6,0) -> 55.728195 | D35: =VLOOKUP($A35,'Реестр объектов'!$A:$I,7,0) -> 37.765938 | E35: Гытлан Роман Валентинович | F35: МФР ШТАБ | G35: 45973.352 | H35: 45973.435 | I35: 120 мин | J35: =VLOOKUP($A35,'Реестр объектов'!$A:$I,8,0) -> https://docs.google.com/spreadsheets/d/1H1MjbG2y0oC0hhID4do1G0_gfyI1jag72lQd7nL3WDQ/edit?gid=1217417878#gid=1217417878 | K35: =VLOOKUP($A35,'Реестр объектов'!$A:$I,9,0) -> https://disk.yandex.ru/client/disk/Осмотры%20объектов%20АНО%20СМГ/532%20район%20Рязанский%2C%20Михайлова%20ул.%2C%20зу%2015
A36: 616 | B36: =VLOOKUP($A36,'Реестр объектов'!$A:$I,5,0) -> Сиреневый б-р, з/у 4/9, зона 6,2 Сиреневый б-р, з/у 4/9, зона 6,2 | C36: =VLOOKUP($A36,'Реестр объектов'!$A:$I,6,0) -> 55.796435 | D36: =VLOOKUP($A36,'Реестр объектов'!$A:$I,7,0) -> 37.761761 | E36: Дрозд Александр Викторович | F36: МФР ШТАБ | G36: 45973.636 | H36: 45973.705 | I36: 100 мин | J36: =VLOOKUP($A36,'Реестр объектов'!$A:$I,8,0) -> https://docs.google.com/spreadsheets/d/1H1MjbG2y0oC0hhID4do1G0_gfyI1jag72lQd7nL3WDQ/edit?gid=632665949#gid=632665949 | K36: =VLOOKUP($A36,'Реестр объектов'!$A:$I,9,0) -> https://disk.yandex.ru/client/disk/Осмотры%20объектов%20АНО%20СМГ/616.%20Измайлово%2C%20Сиреневый%20бульв%20ар%2C%20зу%204.9%2C%20зона%206.2
A37: 566 | B37: =VLOOKUP($A37,'Реестр объектов'!$A:$I,5,0) -> Волгоградский пр-т, вл. 101, корп. 2 район Кузьминки, Волгоградский пр-т, вл. 101, корп. 2 | C37: =VLOOKUP($A37,'Реестр объектов'!$A:$I,6,0) -> 55.708765 | D37: =VLOOKUP($A37,'Реестр объектов'!$A:$I,7,0) -> 37.754512 | E37: Удалкин Иван Вячеславович | F37: МФР ШТАБ | G37: 45974.369 | H37: 45974.467 | I37: 141 мин | J37: =VLOOKUP($A37,'Реестр объектов'!$A:$I,8,0) -> https://docs.google.com/spreadsheets/d/1H1MjbG2y0oC0hhID4do1G0_gfyI1jag72lQd7nL3WDQ/edit?gid=947386880#gid=947386880 | K37: =VLOOKUP($A37,'Реестр объектов'!$A:$I,9,0) -> https://disk.yandex.ru/client/disk/Осмотры%20объектов%20АНО%20СМГ/566.%20район%20Кузьминки%2C%20Волгоградский%20пр-т%2C%20вл.%20101%2C%20корп.%202
A38: 447 | B38: =VLOOKUP($A38,'Реестр объектов'!$A:$I,5,0) -> Камова ул., вл. 24 район Косино-Ухтомский, Камова ул., вл. 24 | C38: =VLOOKUP($A38,'Реестр объектов'!$A:$I,6,0) -> 55.699665 | D38: =VLOOKUP($A38,'Реестр объектов'!$A:$I,7,0) -> 37.875188 | E38: Шурпаев Нажмутдин Гаджиатаевич | F38: МФР ШТАБ | G38: 45973.374 | H38: 45973.447 | I38: 105 мин | J38: =VLOOKUP($A38,'Реестр объектов'!$A:$I,8,0) -> https://docs.google.com/spreadsheets/d/1H1MjbG2y0oC0hhID4do1G0_gfyI1jag72lQd7nL3WDQ/edit?gid=747557076#gid=747557076 | K38: =VLOOKUP($A38,'Реестр объектов'!$A:$I,9,0) -> https://disk.yandex.ru/client/disk/Осмотры%20объектов%20АНО%20СМГ/447.%20район%20Косино-Ухтомский%2C%20ул.%20Камова%2C%20влд.%2024
A39: 588 | B39: =VLOOKUP($A39,'Реестр объектов'!$A:$I,5,0) -> Молодогвардейская ул., з/у 53 (вл. 51, вл. 53) район Кунцево, Молодогвардейская ул., з/у 53 | C39: =VLOOKUP($A39,'Реестр объектов'!$A:$I,6,0) -> 55.733307 | D39: =VLOOKUP($A39,'Реестр объектов'!$A:$I,7,0) -> 37.406168 | E39: Пулатов Алекс Шухратович | F39: МФР ШТАБ | G39: 45973.389 | H39: 45973.466 | I39: 112 мин | J39: =VLOOKUP($A39,'Реестр объектов'!$A:$I,8,0) -> https://docs.google.com/spreadsheets/d/1H1MjbG2y0oC0hhID4do1G0_gfyI1jag72lQd7nL3WDQ/edit?gid=788221100#gid=788221100 | K39: =VLOOKUP($A39,'Реестр объектов'!$A:$I,9,0) -> https://disk.yandex.ru/client/disk/Осмотры%20объектов%20АНО%20СМГ/588.%20жилой%20дом%20ул.%20Молодогвардейская%2053
A40: 556 | B40: =VLOOKUP($A40,'Реестр объектов'!$A:$I,5,0) -> Грайвороново, кв. 90А, корп. 12 район Текстильщики, кв-л Грайвороново 90А, з/у 1 (Грайвороново, квартал 90А) | C40: =VLOOKUP($A40,'Реестр объектов'!$A:$I,6,0) -> 55.721583 | D40: =VLOOKUP($A40,'Реестр объектов'!$A:$I,7,0) -> 37.738602 | E40: Гытлан Роман Валентинович | F40: МФР ШТАБ | G40: 45973.447 | H40: 45973.53 | I40: 119 мин | J40: =VLOOKUP($A40,'Реестр объектов'!$A:$I,8,0) -> https://docs.google.com/spreadsheets/d/1H1MjbG2y0oC0hhID4do1G0_gfyI1jag72lQd7nL3WDQ/edit?gid=1984564802#gid=1984564802 | K40: =VLOOKUP($A40,'Реестр объектов'!$A:$I,9,0) -> https://disk.yandex.ru/client/disk/Осмотры%20объектов%20АНО%20СМГ/556.%20Грайвороново%20кв.%2090.%20корп.%2012
...

Sheet Реестр объектов
D1: https://docs.google.com/spreadsheets/d/1h7Zyn53eByFA_Wa7EnuJEIn9QqPaz6kDse3SZgRdd5g/edit?gid'=0#gid'=0 | J1: {=IF(A14:A1975="", "", IFNA( VLOOKUP( A14:A1975, SORT('АРХИВ'!A:H, ROW('АРХИВ'!A:A), FALSE), 8, FALSE ) ,""))} -> #REF! | M1: {=IF($A$14:$A1975="", "", IF(J14:J1975=100, "", IF(K14:K1975="", "", DATEVALUE(LEFT(K14:K1975, 10)) + L14:L1975)))} -> #REF!
C3: Чеки ДСТИ | D3: https://docs.google.com/spreadsheets/d/1MW8OIVEKRJEaLcG-KS0zwZPEQ0eRUWE2y9Gj77rgoxo/edit?gid=796994001#gid=796994001
C4: Чеги ДРНТ | D4: https://docs.google.com/spreadsheets/d/19THEBTE9q0fhN2eApZr6BgenIvLGh0AckaYxHQfHk5w/edit?gid=0#gid=0
C5: Чеки метро | D5: https://docs.google.com/spreadsheets/d/1jonEGMB3UFHiUZpltF1zURon8gYN7jGSHu-k9t5TXnA/edit?gid=0#gid=0
C6: Чеки Рен-25 | D6: https://docs.google.com/spreadsheets/d/1H1MjbG2y0oC0hhID4do1G0_gfyI1jag72lQd7nL3WDQ/edit?gid=0#gid=0
C7: Чеки Рен-26 | D7: https://docs.google.com/spreadsheets/d/1rbCD10ySi4YZEkJW2_Slmn9z7AI1WEsGsZaIJmnnT18/edit?gid=0#gid=0
C8: Чеки Рен-27 | D8: https://docs.google.com/spreadsheets/d/1lEcUd4exxkr5Za3IYZ0vdFNfMubnuMOOMXfmF3GYC9I/edit?gid=0#gid=0
C9: Чеки вне списка | D9: https://docs.google.com/spreadsheets/d/1EI7qusa674eJhuaw-nWWtWMEHVSYMQv7HLsInEZTWpE/edit?gid=0#gid=0
A12: ID | B12: Список | C12: Вид | D12: Внебюджет | E12: Adress | F12: latitude | G12: longitude | H12: chek | I12: yandex | J12: СГ | K12: Последний объезд | L12: Периодичность | M12: Плановая дата | N12: Статус
A13: =IFERROR(__xludf.DUMMYFUNCTION("QUERY(IMPORTRANGE(D1, ""АИП 25-27 / РЕН 25-27 / ВНЕ СПИСКА!A:ZZ""), ""SELECT Col6, Col4, Col5, Col38, Col52,Col55,Col56,Col53, Col54, Col28, Col30 OFFSET 12"", 1)"),"6") -> 6 | B13: =IFERROR(__xludf.DUMMYFUNCTION("""COMPUTED_VALUE"""),"4") -> 4 | C13: =IFERROR(__xludf.DUMMYFUNCTION("""COMPUTED_VALUE"""),"7") -> 7 | D13: =IFERROR(__xludf.DUMMYFUNCTION("""COMPUTED_VALUE"""),"38") -> 38 | E13: =IFERROR(__xludf.DUMMYFUNCTION("""COMPUTED_VALUE"""),"") | F13: =IFERROR(__xludf.DUMMYFUNCTION("""COMPUTED_VALUE"""),"") | G13: =IFERROR(__xludf.DUMMYFUNCTION("""COMPUTED_VALUE"""),"") | H13: =IFERROR(__xludf.DUMMYFUNCTION("""COMPUTED_VALUE"""),"") | I13: =IFERROR(__xludf.DUMMYFUNCTION("""COMPUTED_VALUE"""),"") | J13: =IFERROR(__xludf.DUMMYFUNCTION("""COMPUTED_VALUE"""),"28") -> 28 | K13: =IFERROR(__xludf.DUMMYFUNCTION("""COMPUTED_VALUE"""),"32") -> 32
A14: =IFERROR(__xludf.DUMMYFUNCTION("""COMPUTED_VALUE"""),"006") -> 006 | B14: =IFERROR(__xludf.DUMMYFUNCTION("""COMPUTED_VALUE"""),"АИП-25") -> АИП-25 | C14: =IFERROR(__xludf.DUMMYFUNCTION("""COMPUTED_VALUE"""),"ОКС") -> ОКС | E14: =IFERROR(__xludf.DUMMYFUNCTION("""COMPUTED_VALUE"""),"Осмотр итогов строительства объекта административного здания на территории поселения Внуковское район Внуково, поселение Внуковское, ул. Авиаконструктора Петлякова") -> Осмотр итогов строительства объекта административного здания на территории поселения Внуковское район Внуково, поселение Внуковское, ул. Авиаконструктора Петлякова | F14: =IFERROR(__xludf.DUMMYFUNCTION("""COMPUTED_VALUE"""),"#N/A") -> #N/A | G14: =IFERROR(__xludf.DUMMYFUNCTION("""COMPUTED_VALUE"""),"#N/A") -> #N/A | H14: =IFERROR(__xludf.DUMMYFUNCTION("""COMPUTED_VALUE"""),"https://docs.google.com/spreadsheets/d/19THEBTE9q0fhN2eApZr6BgenIvLGh0AckaYxHQfHk5w/edit?gid=1222968113#gid=1222968113") -> https://docs.google.com/spreadsheets/d/19THEBTE9q0fhN2eApZr6BgenIvLGh0AckaYxHQfHk5w/edit?gid=1222968113#gid=1222968113 | I14: =IFERROR(__xludf.DUMMYFUNCTION("""COMPUTED_VALUE"""),"https://disk.yandex.ru/client/disk/Осмотры%20объектов%20АНО%20СМГ/006.%20Административное%20здание%20на%20тер%20Внуковское%20д%20Лапшинка") -> https://disk.yandex.ru/client/disk/Осмотры%20объектов%20АНО%20СМГ/006.%20Административное%20здание%20на%20тер%20Внуковское%20д%20Лапшинка | J14: =IFERROR(__xludf.DUMMYFUNCTION("""COMPUTED_VALUE"""),100.0) -> 100 | K14: =IFERROR(__xludf.DUMMYFUNCTION("""COMPUTED_VALUE"""),45909.0) -> 45909 | L14: {=IF(A14:A1975="", "", IF(J14:J1975=100, "Завершен", IF(J14:J1975<=50, 30, IF(J14:J1975<=94, 14, 7))))} -> Завершен | M14: {=IF(A14:A1975="", "", IF(J14:J1975=100, "", IF(K14:K1975="", "", DATEVALUE(LEFT(K14:K1975, 10)) + L14:L1975)))} | N14: {=IF(A14:A1975="", "", IF(J14:J1975=100, "✅ Завершен", IF(LEFT(O14:O1975, 2)="РВ", "🔴 Объект введен", IF(K14:K1975="", "🆕 Нет объездов", IF(TODAY() - DATEVALUE(LEFT(K14:K1975, 10)) > L14:L1975, "🔴 ПРОСРОЧЕН", IF(L14:L1975 = 30, IF(TODAY() - DATEVALUE(LEFT(K14:K1975, 10)) > 23, "🔴 СРОЧНО", IF(TODAY() - DATEVALUE(LEFT(K14:K1975, 10)) > 16, "🟠 ВНИМАНИЕ", IF(TODAY() - DATEVALUE(LEFT(K14:K1975, 10)) > 9, "🟡 СКОРО", "🟢 ПО ПЛАНУ"))), IF(L14:L1975 = 14, IF(TODAY() - DATEVALUE(LEFT(K14:K1975, 10)) > 11, "🔴 СРОЧНО", IF(TODAY() - DATEVALUE(LEFT(K14:K1975, 10)) > 7, "🟠 ВНИМАНИЕ", IF(TODAY() - DATEVALUE(LEFT(K14:K1975, 10)) > 4, "🟡 СКОРО", "🟢 ПО ПЛАНУ"))), IF(TODAY() - DATEVALUE(LEFT(K14:K1975, 10)) > 6, "🔴 СРОЧНО", IF(TODAY() - DATEVALUE(LEFT(K14:K1975, 10)) > 4, "🟠 ВНИМАНИЕ", IF(TODAY() - DATEVALUE(LEFT(K14:K1975, 10)) > 2, "🟡 СКОРО", "🟢 ПО ПЛАНУ"))) ))) ))) )} -> ✅ Завершен | O14: РВ от 14.03.2025 № 77-17-012472-2025 По состоянию на 09.09.2025 Произошла смена Заказчика Не передана исполнительная документация по объекту в полном объеме
A15: =IFERROR(__xludf.DUMMYFUNCTION("""COMPUTED_VALUE"""),"160д") -> 160д | B15: =IFERROR(__xludf.DUMMYFUNCTION("""COMPUTED_VALUE"""),"АИП-25") -> АИП-25 | C15: =IFERROR(__xludf.DUMMYFUNCTION("""COMPUTED_VALUE"""),"УДС") -> УДС | E15: =IFERROR(__xludf.DUMMYFUNCTION("""COMPUTED_VALUE"""),"Развитие улично-дорожной сети городского округа Троицк (2 этап). (Строительство магистральной улицы районного значения от ул. Полковника милиции Курочкина до Октябрьского проспекта (Подъездная дорога к школе на 2100 мест в микрорайоне ""В"" г.о. Троицк в "&"городе Москве) Троицк") -> Развитие улично-дорожной сети городского округа Троицк (2 этап). (Строительство магистральной улицы районного значения от ул. Полковника милиции Курочкина до Октябрьского проспекта (Подъездная дорога к школе на 2100 мест в микрорайоне "В" г.о. Троицк в городе Москве) Троицк | F15: =IFERROR(__xludf.DUMMYFUNCTION("""COMPUTED_VALUE"""),"#N/A") -> #N/A | G15: =IFERROR(__xludf.DUMMYFUNCTION("""COMPUTED_VALUE"""),"#N/A") -> #N/A | J15: =IFERROR(__xludf.DUMMYFUNCTION("""COMPUTED_VALUE"""),98.0) -> 98 | K15: =IFERROR(__xludf.DUMMYFUNCTION("""COMPUTED_VALUE"""),45968.0) -> 45968 | L15: 7 | M15: 45975 | N15: 🔴 Объект введен | O15: РВ от 26.03.2025 № 77-19-012479-2025
A16: =IFERROR(__xludf.DUMMYFUNCTION("""COMPUTED_VALUE"""),"384д") -> 384д | B16: =IFERROR(__xludf.DUMMYFUNCTION("""COMPUTED_VALUE"""),"АИП-25") -> АИП-25 | C16: =IFERROR(__xludf.DUMMYFUNCTION("""COMPUTED_VALUE"""),"УДС") -> УДС | E16: =IFERROR(__xludf.DUMMYFUNCTION("""COMPUTED_VALUE"""),"Строительство автомобильной дороги ""Воскресенское - Каракашево - Щербинка"". этап: Этап 5.1 (ОРП) Воскресенское") -> Строительство автомобильной дороги "Воскресенское - Каракашево - Щербинка". этап: Этап 5.1 (ОРП) Воскресенское | F16: =IFERROR(__xludf.DUMMYFUNCTION("""COMPUTED_VALUE"""),"#N/A") -> #N/A | G16: =IFERROR(__xludf.DUMMYFUNCTION("""COMPUTED_VALUE"""),"#N/A") -> #N/A | J16: =IFERROR(__xludf.DUMMYFUNCTION("""COMPUTED_VALUE"""),100.0) -> 100 | K16: =IFERROR(__xludf.DUMMYFUNCTION("""COMPUTED_VALUE"""),45972.0) -> 45972 | L16: Завершен | N16: ✅ Завершен | O16: РВ от 10.03.2025 № 77-17-012467-2025
A17: =IFERROR(__xludf.DUMMYFUNCTION("""COMPUTED_VALUE"""),"012") -> 012 | B17: =IFERROR(__xludf.DUMMYFUNCTION("""COMPUTED_VALUE"""),"АИП-25") -> АИП-25 | C17: =IFERROR(__xludf.DUMMYFUNCTION("""COMPUTED_VALUE"""),"ОКС") -> ОКС | E17: =IFERROR(__xludf.DUMMYFUNCTION("""COMPUTED_VALUE"""),"Реконструкция школы № 2062 на 350 мест со строительством пристройки на 550 мест (2-й этап - реконструкция) ТАО, Новофёдоровское, д. Яковлевское, д. 29") -> Реконструкция школы № 2062 на 350 мест со строительством пристройки на 550 мест (2-й этап - реконструкция) ТАО, Новофёдоровское, д. Яковлевское, д. 29 | F17: =IFERROR(__xludf.DUMMYFUNCTION("""COMPUTED_VALUE"""),"#N/A") -> #N/A | G17: =IFERROR(__xludf.DUMMYFUNCTION("""COMPUTED_VALUE"""),"#N/A") -> #N/A | H17: =IFERROR(__xludf.DUMMYFUNCTION("""COMPUTED_VALUE"""),"https://docs.google.com/spreadsheets/d/19THEBTE9q0fhN2eApZr6BgenIvLGh0AckaYxHQfHk5w/edit?gid=1038633275#gid=1038633275") -> https://docs.google.com/spreadsheets/d/19THEBTE9q0fhN2eApZr6BgenIvLGh0AckaYxHQfHk5w/edit?gid=1038633275#gid=1038633275 | I17: =IFERROR(__xludf.DUMMYFUNCTION("""COMPUTED_VALUE"""),"https://disk.yandex.ru/client/disk/Осмотры%20объектов%20АНО%20СМГ/012.%20новофедоровское%20СОШ%202062") -> https://disk.yandex.ru/client/disk/Осмотры%20объектов%20АНО%20СМГ/012.%20новофедоровское%20СОШ%202062 | J17: =IFERROR(__xludf.DUMMYFUNCTION("""COMPUTED_VALUE"""),100.0) -> 100 | K17: =IFERROR(__xludf.DUMMYFUNCTION("""COMPUTED_VALUE"""),45889.0) -> 45889 | L17: Завершен | N17: ✅ Завершен | O17: РВ от 21.03.2025 №77-21-012476-2025
A18: =IFERROR(__xludf.DUMMYFUNCTION("""COMPUTED_VALUE"""),"120") -> 120 | B18: =IFERROR(__xludf.DUMMYFUNCTION("""COMPUTED_VALUE"""),"АИП-25") -> АИП-25 | C18: =IFERROR(__xludf.DUMMYFUNCTION("""COMPUTED_VALUE"""),"ОКС") -> ОКС | E18: =IFERROR(__xludf.DUMMYFUNCTION("""COMPUTED_VALUE"""),"Учебный корпус на 400 мест (этап 2) ориентир ул. Базовская, д. 15, корп.13 район Западное Дегунино, ул. Базовская, д. 15, корп. 13") -> Учебный корпус на 400 мест (этап 2) ориентир ул. Базовская, д. 15, корп.13 район Западное Дегунино, ул. Базовская, д. 15, корп. 13 | F18: =IFERROR(__xludf.DUMMYFUNCTION("""COMPUTED_VALUE"""),"#N/A") -> #N/A | G18: =IFERROR(__xludf.DUMMYFUNCTION("""COMPUTED_VALUE"""),"#N/A") -> #N/A | H18: =IFERROR(__xludf.DUMMYFUNCTION("""COMPUTED_VALUE"""),"https://docs.google.com/spreadsheets/d/19THEBTE9q0fhN2eApZr6BgenIvLGh0AckaYxHQfHk5w/edit?gid=717172873#gid=717172873") -> https://docs.google.com/spreadsheets/d/19THEBTE9q0fhN2eApZr6BgenIvLGh0AckaYxHQfHk5w/edit?gid=717172873#gid=717172873 | I18: =IFERROR(__xludf.DUMMYFUNCTION("""COMPUTED_VALUE"""),"https://disk.yandex.ru/client/disk/Осмотры%20объектов%20АНО%20СМГ/120.%20Базовская%20д15%20корп%2013") -> https://disk.yandex.ru/client/disk/Осмотры%20объектов%20АНО%20СМГ/120.%20Базовская%20д15%20корп%2013 | J18: =IFERROR(__xludf.DUMMYFUNCTION("""COMPUTED_VALUE"""),99.9685) -> 99.9685 | K18: =IFERROR(__xludf.DUMMYFUNCTION("""COMPUTED_VALUE"""),45889.0) -> 45889 | L18: 7 | M18: 45896 | N18: 🔴 Объект введен | O18: РВ от 03.03.2025 №77-09-012464-2025
A19: =IFERROR(__xludf.DUMMYFUNCTION("""COMPUTED_VALUE"""),"125") -> 125 | B19: =IFERROR(__xludf.DUMMYFUNCTION("""COMPUTED_VALUE"""),"АИП-25") -> АИП-25 | C19: =IFERROR(__xludf.DUMMYFUNCTION("""COMPUTED_VALUE"""),"ОКС") -> ОКС | E19: =IFERROR(__xludf.DUMMYFUNCTION("""COMPUTED_VALUE"""),"Скоропомощный стационарный комплекс на территории ГБУЗ «ГКБ им. В.М. Буянова» ДЗМ ул. Бакинская, д. 26 район Царицино, ул. Бакинская, д. 26 (со сносом объектов по адресам: Бакинская ул., д. 26, стр. 6, стр. 8)") -> Скоропомощный стационарный комплекс на территории ГБУЗ «ГКБ им. В.М. Буянова» ДЗМ ул. Бакинская, д. 26 район Царицино, ул. Бакинская, д. 26 (со сносом объектов по адресам: Бакинская ул., д. 26, стр. 6, стр. 8) | F19: =IFERROR(__xludf.DUMMYFUNCTION("""COMPUTED_VALUE"""),"#N/A") -> #N/A | G19: =IFERROR(__xludf.DUMMYFUNCTION("""COMPUTED_VALUE"""),"#N/A") -> #N/A | H19: =IFERROR(__xludf.DUMMYFUNCTION("""COMPUTED_VALUE"""),"https://docs.google.com/spreadsheets/d/19THEBTE9q0fhN2eApZr6BgenIvLGh0AckaYxHQfHk5w/edit?gid=2058696561#gid=2058696561") -> https://docs.google.com/spreadsheets/d/19THEBTE9q0fhN2eApZr6BgenIvLGh0AckaYxHQfHk5w/edit?gid=2058696561#gid=2058696561 | I19: =IFERROR(__xludf.DUMMYFUNCTION("""COMPUTED_VALUE"""),"https://disk.yandex.ru/client/disk/Осмотры%20объектов%20АНО%20СМГ/125.%20ГКБ%20им.%20В.И.%20Буянова%20ДЗМ%20Царицино%20ЮАО%20г.%20Москва%20Бакинская%20д.%2026%20с.%208") -> https://disk.yandex.ru/client/disk/Осмотры%20объектов%20АНО%20СМГ/125.%20ГКБ%20им.%20В.И.%20Буянова%20ДЗМ%20Царицино%20ЮАО%20г.%20Москва%20Бакинская%20д.%2026%20с.%208 | J19: =IFERROR(__xludf.DUMMYFUNCTION("""COMPUTED_VALUE"""),100.0) -> 100 | K19: =IFERROR(__xludf.DUMMYFUNCTION("""COMPUTED_VALUE"""),45828.0) -> 45828 | L19: Завершен | N19: ✅ Завершен | O19: РВ от 14.04.2025 №77-05-012515-2025
A20: =IFERROR(__xludf.DUMMYFUNCTION("""COMPUTED_VALUE"""),"259") -> 259 | B20: =IFERROR(__xludf.DUMMYFUNCTION("""COMPUTED_VALUE"""),"АИП-25") -> АИП-25 | C20: =IFERROR(__xludf.DUMMYFUNCTION("""COMPUTED_VALUE"""),"ОКС") -> ОКС | E20: =IFERROR(__xludf.DUMMYFUNCTION("""COMPUTED_VALUE"""),"Физкультурно-оздоровительный комплекс, ул. Павла Корчагина, вл. 7 район Алексеевский, ул. Павла Корчагина, вл. 7") -> Физкультурно-оздоровительный комплекс, ул. Павла Корчагина, вл. 7 район Алексеевский, ул. Павла Корчагина, вл. 7 | F20: =IFERROR(__xludf.DUMMYFUNCTION("""COMPUTED_VALUE"""),"#N/A") -> #N/A | G20: =IFERROR(__xludf.DUMMYFUNCTION("""COMPUTED_VALUE"""),"#N/A") -> #N/A | H20: =IFERROR(__xludf.DUMMYFUNCTION("""COMPUTED_VALUE"""),"https://docs.google.com/spreadsheets/d/19THEBTE9q0fhN2eApZr6BgenIvLGh0AckaYxHQfHk5w/edit?gid=600337697#gid=600337697") -> https://docs.google.com/spreadsheets/d/19THEBTE9q0fhN2eApZr6BgenIvLGh0AckaYxHQfHk5w/edit?gid=600337697#gid=600337697 | I20: =IFERROR(__xludf.DUMMYFUNCTION("""COMPUTED_VALUE"""),"https://disk.yandex.ru/client/disk/Осмотры%20объектов%20АНО%20СМГ/259.%20ул%20Павла%20Корчагина%2C%207") -> https://disk.yandex.ru/client/disk/Осмотры%20объектов%20АНО%20СМГ/259.%20ул%20Павла%20Корчагина%2C%207 | J20: =IFERROR(__xludf.DUMMYFUNCTION("""COMPUTED_VALUE"""),100.0) -> 100 | K20: =IFERROR(__xludf.DUMMYFUNCTION("""COMPUTED_VALUE"""),45828.0) -> 45828 | L20: Завершен | N20: ✅ Завершен | O20: РВ от 27.02.2025 № 77-02-012458-2025
A21: =IFERROR(__xludf.DUMMYFUNCTION("""COMPUTED_VALUE"""),"101") -> 101 | B21: =IFERROR(__xludf.DUMMYFUNCTION("""COMPUTED_VALUE"""),"АИП-25") -> АИП-25 | C21: =IFERROR(__xludf.DUMMYFUNCTION("""COMPUTED_VALUE"""),"ОКС") -> ОКС | E21: =IFERROR(__xludf.DUMMYFUNCTION("""COMPUTED_VALUE"""),"Жилой комплекс «Царицыно» подземный паркинг с благоустройством 6-я Радиальная ул., вл. 7 (корп. 5.4) район Бирюлево Восточное, 6-я Радиальная ул, вл. 7 (корп. 5.4)") -> Жилой комплекс «Царицыно» подземный паркинг с благоустройством 6-я Радиальная ул., вл. 7 (корп. 5.4) район Бирюлево Восточное, 6-я Радиальная ул, вл. 7 (корп. 5.4) | F21: =IFERROR(__xludf.DUMMYFUNCTION("""COMPUTED_VALUE"""),"#N/A") -> #N/A | G21: =IFERROR(__xludf.DUMMYFUNCTION("""COMPUTED_VALUE"""),"#N/A") -> #N/A | H21: =IFERROR(__xludf.DUMMYFUNCTION("""COMPUTED_VALUE"""),"https://docs.google.com/spreadsheets/d/19THEBTE9q0fhN2eApZr6BgenIvLGh0AckaYxHQfHk5w/edit?gid=23825357#gid=23825357") -> https://docs.google.com/spreadsheets/d/19THEBTE9q0fhN2eApZr6BgenIvLGh0AckaYxHQfHk5w/edit?gid=23825357#gid=23825357 | I21: =IFERROR(__xludf.DUMMYFUNCTION("""COMPUTED_VALUE"""),"https://disk.yandex.ru/client/disk/Осмотры%20объектов%20АНО%20СМГ/101.%20Подземный%20паркинг.%20ЖК%20%22Царицыно%22.%206-я%20Радиальная%20ул.%2C%20вл.%207%20(корп%205.4)") -> https://disk.yandex.ru/client/disk/Осмотры%20объектов%20АНО%20СМГ/101.%20Подземный%20паркинг.%20ЖК%20%22Царицыно%22.%206-я%20Радиальная%20ул.%2C%20вл.%207%20(корп%205.4) | J21: =IFERROR(__xludf.DUMMYFUNCTION("""COMPUTED_VALUE"""),99.724875) -> 99.724875 | K21: =IFERROR(__xludf.DUMMYFUNCTION("""COMPUTED_VALUE"""),45861.0) -> 45861 | L21: 7 | M21: 45868 | N21: 🔴 Объект введен | O21: РВ от 27.03.2025 № 77-05-012481-2025
A22: =IFERROR(__xludf.DUMMYFUNCTION("""COMPUTED_VALUE"""),"100") -> 100 | B22: =IFERROR(__xludf.DUMMYFUNCTION("""COMPUTED_VALUE"""),"АИП-25") -> АИП-25 | C22: =IFERROR(__xludf.DUMMYFUNCTION("""COMPUTED_VALUE"""),"ОКС") -> ОКС | E22: =IFERROR(__xludf.DUMMYFUNCTION("""COMPUTED_VALUE"""),"Жилой комплекс «Царицыно» подземный паркинг с благоустройством 6-я Радиальная ул., вл. 7 (корп. 5.1) район Бирюлево Восточное, 6-я Радиальная ул, вл. 7 (корп. 5.1)") -> Жилой комплекс «Царицыно» подземный паркинг с благоустройством 6-я Радиальная ул., вл. 7 (корп. 5.1) район Бирюлево Восточное, 6-я Радиальная ул, вл. 7 (корп. 5.1) | F22: =IFERROR(__xludf.DUMMYFUNCTION("""COMPUTED_VALUE"""),"#N/A") -> #N/A | G22: =IFERROR(__xludf.DUMMYFUNCTION("""COMPUTED_VALUE"""),"#N/A") -> #N/A | H22: =IFERROR(__xludf.DUMMYFUNCTION("""COMPUTED_VALUE"""),"https://docs.google.com/spreadsheets/d/19THEBTE9q0fhN2eApZr6BgenIvLGh0AckaYxHQfHk5w/edit?gid=1122822598#gid=1122822598") -> https://docs.google.com/spreadsheets/d/19THEBTE9q0fhN2eApZr6BgenIvLGh0AckaYxHQfHk5w/edit?gid=1122822598#gid=1122822598 | I22: =IFERROR(__xludf.DUMMYFUNCTION("""COMPUTED_VALUE"""),"https://disk.yandex.ru/client/disk/Осмотры%20объектов%20АНО%20СМГ/100.%20Подземный%20паркинг.%20ЖК%20%22Царицыно%22.%206-я%20Радиальная%20ул.%20%2C%20вл.%207%20(корп.%205.1)") -> https://disk.yandex.ru/client/disk/Осмотры%20объектов%20АНО%20СМГ/100.%20Подземный%20паркинг.%20ЖК%20%22Царицыно%22.%206-я%20Радиальная%20ул.%20%2C%20вл.%207%20(корп.%205.1) | J22: =IFERROR(__xludf.DUMMYFUNCTION("""COMPUTED_VALUE"""),99.6405) -> 99.6405 | K22: =IFERROR(__xludf.DUMMYFUNCTION("""COMPUTED_VALUE"""),45861.0) -> 45861 | L22: 7 | M22: 45868 | N22: 🔴 Объект введен | O22: РВ от 28.03.2025 № 77-05-012483-2025
A23: =IFERROR(__xludf.DUMMYFUNCTION("""COMPUTED_VALUE"""),"123") -> 123 | B23: =IFERROR(__xludf.DUMMYFUNCTION("""COMPUTED_VALUE"""),"АИП-25") -> АИП-25 | C23: =IFERROR(__xludf.DUMMYFUNCTION("""COMPUTED_VALUE"""),"ОКС") -> ОКС | E23: =IFERROR(__xludf.DUMMYFUNCTION("""COMPUTED_VALUE"""),"Жилой комплекс «Терлецкий парк» Новогиреевская ул., вл.5, корп.1, корп.2 район Новогиреево, Новогиреевская ул., вл. 5, корп. 1, корп. 2") -> Жилой комплекс «Терлецкий парк» Новогиреевская ул., вл.5, корп.1, корп.2 район Новогиреево, Новогиреевская ул., вл. 5, корп. 1, корп. 2 | F23: =IFERROR(__xludf.DUMMYFUNCTION("""COMPUTED_VALUE"""),"55.761429") -> 55.761429 | G23: =IFERROR(__xludf.DUMMYFUNCTION("""COMPUTED_VALUE"""),"37.796085") -> 37.796085 | H23: =IFERROR(__xludf.DUMMYFUNCTION("""COMPUTED_VALUE"""),"https://docs.google.com/spreadsheets/d/19THEBTE9q0fhN2eApZr6BgenIvLGh0AckaYxHQfHk5w/edit?gid=326698304#gid=326698304") -> https://docs.google.com/spreadsheets/d/19THEBTE9q0fhN2eApZr6BgenIvLGh0AckaYxHQfHk5w/edit?gid=326698304#gid=326698304 | I23: =IFERROR(__xludf.DUMMYFUNCTION("""COMPUTED_VALUE"""),"https://disk.yandex.ru/client/disk/Осмотры%20объектов%20АНО%20СМГ/123.%20ЖК%20«Терлецкий%20Парк»%20Новогиреевская%20ул.%2C%20вл.5%2C%20корп.1%2C%20корп.2") -> https://disk.yandex.ru/client/disk/Осмотры%20объектов%20АНО%20СМГ/123.%20ЖК%20«Терлецкий%20Парк»%20Новогиреевская%20ул.%2C%20вл.5%2C%20корп.1%2C%20корп.2 | J23: =IFERROR(__xludf.DUMMYFUNCTION("""COMPUTED_VALUE"""),99.757125) -> 99.757125 | K23: =IFERROR(__xludf.DUMMYFUNCTION("""COMPUTED_VALUE"""),45901.0) -> 45901 | L23: 7 | M23: 45908 | N23: 🔴 Объект введен | O23: РВ от 10.04.2025 № 77-03-012509-2025
A24: =IFERROR(__xludf.DUMMYFUNCTION("""COMPUTED_VALUE"""),"118") -> 118 | B24: =IFERROR(__xludf.DUMMYFUNCTION("""COMPUTED_VALUE"""),"АИП-25") -> АИП-25 | C24: =IFERROR(__xludf.DUMMYFUNCTION("""COMPUTED_VALUE"""),"ОКС") -> ОКС | E24: =IFERROR(__xludf.DUMMYFUNCTION("""COMPUTED_VALUE"""),"Жилой комплекс «Царицыно» подземный паркинг с благоустройством 6-я Радиальная ул., вл. 7 (корп. 30,31) район Бирюлево Восточное, 6-я Радиальная ул, вл. 7 (корп. 30, 31)") -> Жилой комплекс «Царицыно» подземный паркинг с благоустройством 6-я Радиальная ул., вл. 7 (корп. 30,31) район Бирюлево Восточное, 6-я Радиальная ул, вл. 7 (корп. 30, 31) | F24: =IFERROR(__xludf.DUMMYFUNCTION("""COMPUTED_VALUE"""),"#N/A") -> #N/A | G24: =IFERROR(__xludf.DUMMYFUNCTION("""COMPUTED_VALUE"""),"#N/A") -> #N/A | H24: =IFERROR(__xludf.DUMMYFUNCTION("""COMPUTED_VALUE"""),"https://docs.google.com/spreadsheets/d/19THEBTE9q0fhN2eApZr6BgenIvLGh0AckaYxHQfHk5w/edit?gid=739392640#gid=739392640") -> https://docs.google.com/spreadsheets/d/19THEBTE9q0fhN2eApZr6BgenIvLGh0AckaYxHQfHk5w/edit?gid=739392640#gid=739392640 | I24: =IFERROR(__xludf.DUMMYFUNCTION("""COMPUTED_VALUE"""),"https://disk.yandex.ru/client/disk/Осмотры%20объектов%20АНО%20СМГ/118.%206-я%20Радиальная%20ул.%2C%20вл.%207%20корп.%2030%2C%2031.%20Паркинг") -> https://disk.yandex.ru/client/disk/Осмотры%20объектов%20АНО%20СМГ/118.%206-я%20Радиальная%20ул.%2C%20вл.%207%20корп.%2030%2C%2031.%20Паркинг | J24: =IFERROR(__xludf.DUMMYFUNCTION("""COMPUTED_VALUE"""),99.87412499999999) -> 99.874125 | K24: =IFERROR(__xludf.DUMMYFUNCTION("""COMPUTED_VALUE"""),45861.0) -> 45861 | L24: 7 | M24: 45868 | N24: 🔴 Объект введен | O24: РВ №77-05-012497-2025 от 01.04.2025
A25: =IFERROR(__xludf.DUMMYFUNCTION("""COMPUTED_VALUE"""),"117") -> 117 | B25: =IFERROR(__xludf.DUMMYFUNCTION("""COMPUTED_VALUE"""),"АИП-25") -> АИП-25 | C25: =IFERROR(__xludf.DUMMYFUNCTION("""COMPUTED_VALUE"""),"ОКС") -> ОКС | E25: =IFERROR(__xludf.DUMMYFUNCTION("""COMPUTED_VALUE"""),"Жилой комплекс «Царицыно» подземный паркинг с благоустройством 6-я Радиальная ул., вл. 7 (корп. 27, 28/29) район Бирюлево Восточное, 6-я Радиальная ул, вл. 7 (корп. 27, 28/29)") -> Жилой комплекс «Царицыно» подземный паркинг с благоустройством 6-я Радиальная ул., вл. 7 (корп. 27, 28/29) район Бирюлево Восточное, 6-я Радиальная ул, вл. 7 (корп. 27, 28/29) | F25: =IFERROR(__xludf.DUMMYFUNCTION("""COMPUTED_VALUE"""),"#N/A") -> #N/A | G25: =IFERROR(__xludf.DUMMYFUNCTION("""COMPUTED_VALUE"""),"#N/A") -> #N/A | H25: =IFERROR(__xludf.DUMMYFUNCTION("""COMPUTED_VALUE"""),"https://docs.google.com/spreadsheets/d/19THEBTE9q0fhN2eApZr6BgenIvLGh0AckaYxHQfHk5w/edit?gid=891835937#gid=891835937") -> https://docs.google.com/spreadsheets/d/19THEBTE9q0fhN2eApZr6BgenIvLGh0AckaYxHQfHk5w/edit?gid=891835937#gid=891835937 | I25: =IFERROR(__xludf.DUMMYFUNCTION("""COMPUTED_VALUE"""),"https://disk.yandex.ru/client/disk/Осмотры%20объектов%20АНО%20СМГ/117.%206-я%20Радиальная%20вл.7%20Корп%2027%2C%2028-29.%20Паркинг") -> https://disk.yandex.ru/client/disk/Осмотры%20объектов%20АНО%20СМГ/117.%206-я%20Радиальная%20вл.7%20Корп%2027%2C%2028-29.%20Паркинг | J25: =IFERROR(__xludf.DUMMYFUNCTION("""COMPUTED_VALUE"""),99.86449999999999) -> 99.8645 | K25: =IFERROR(__xludf.DUMMYFUNCTION("""COMPUTED_VALUE"""),45861.0) -> 45861 | L25: 7 | M25: 45868 | N25: 🔴 Объект введен | O25: РВ №77-05-012493-2025 от 31.03.2025
A26: =IFERROR(__xludf.DUMMYFUNCTION("""COMPUTED_VALUE"""),"1034") -> 1034 | B26: =IFERROR(__xludf.DUMMYFUNCTION("""COMPUTED_VALUE"""),"АИП-25") -> АИП-25 | C26: =IFERROR(__xludf.DUMMYFUNCTION("""COMPUTED_VALUE"""),"УДС") -> УДС | E26: =IFERROR(__xludf.DUMMYFUNCTION("""COMPUTED_VALUE"""),"Пересадка на ст. ""Текстильщики"" (с БКЛ на ТКЛ) район Текстильщики, Пересадка на ст. ""Текстильщики"" (с БКЛ на ТКЛ)") -> Пересадка на ст. "Текстильщики" (с БКЛ на ТКЛ) район Текстильщики, Пересадка на ст. "Текстильщики" (с БКЛ на ТКЛ) | F26: =IFERROR(__xludf.DUMMYFUNCTION("""COMPUTED_VALUE"""),"55.708579") -> 55.708579 | G26: =IFERROR(__xludf.DUMMYFUNCTION("""COMPUTED_VALUE"""),"37.728959") -> 37.728959 | H26: =IFERROR(__xludf.DUMMYFUNCTION("""COMPUTED_VALUE"""),"https://docs.google.com/spreadsheets/d/1jonEGMB3UFHiUZpltF1zURon8gYN7jGSHu-k9t5TXnA/edit?gid=808640473#gid=808640473") -> https://docs.google.com/spreadsheets/d/1jonEGMB3UFHiUZpltF1zURon8gYN7jGSHu-k9t5TXnA/edit?gid=808640473#gid=808640473 | I26: =IFERROR(__xludf.DUMMYFUNCTION("""COMPUTED_VALUE"""),"https://disk.yandex.ru/client/disk/Осмотры%20объектов%20АНО%20СМГ/1034.%20Пересадка%20на%20станции%20метро%20Текстильщики%20(с%20БКЛ%20на%20ТКЛ)") -> https://disk.yandex.ru/client/disk/Осмотры%20объектов%20АНО%20СМГ/1034.%20Пересадка%20на%20станции%20метро%20Текстильщики%20(с%20БКЛ%20на%20ТКЛ) | J26: =IFERROR(__xludf.DUMMYFUNCTION("""COMPUTED_VALUE"""),99.9625) -> 99.9625 | K26: =IFERROR(__xludf.DUMMYFUNCTION("""COMPUTED_VALUE"""),45957.0) -> 45957 | L26: 7 | M26: 45964 | N26: 🔴 Объект введен | O26: РВ от 30.04.2025 № 77-04-012528-2025 По состоянию на 01.11.2025 Производяться работы по утранению замечаний ГУП «Московский метрополитен». Из 473 шт. замечаний устранено 441 шт. Плановая дата передачи 5-ти оставшихся помещений - 28.11.2025
